2024-01-25 16:57:26,825 _channel.py [line:246] ERROR Exception in callback <function InferenceServerClient.async_infer.<locals>.wrapped_callback at 0x0000025F86D729D0>: TypeError("callback() missing 4 required positional arguments: 'redis_client', 'tasks_id', 'category', and 'user_id'")
2024-01-25 16:58:35,341 _channel.py [line:246] ERROR Exception in callback <function InferenceServerClient.async_infer.<locals>.wrapped_callback at 0x000001E10E819310>: TypeError("callback() missing 4 required positional arguments: 'redis_client', 'tasks_id', 'category', and 'user_id'")
2024-01-25 17:01:01,301 _channel.py [line:246] ERROR Exception in callback <function InferenceServerClient.async_infer.<locals>.wrapped_callback at 0x0000026887D0D280>: TypeError("callback() missing 3 required positional arguments: 'tasks_id', 'category', and 'user_id'")
2024-01-25 17:02:19,706 _channel.py [line:246] ERROR Exception in callback <function InferenceServerClient.async_infer.<locals>.wrapped_callback at 0x000001F6CD1AA280>: TypeError("callback() got multiple values for argument 'result'")
2024-01-25 17:03:07,480 _channel.py [line:246] ERROR Exception in callback <function InferenceServerClient.async_infer.<locals>.wrapped_callback at 0x000002208E237280>: TypeError("callback() got multiple values for argument 'result'")
2024-01-25 17:05:40,234 _channel.py [line:246] ERROR Exception in callback <function InferenceServerClient.async_infer.<locals>.wrapped_callback at 0x0000017107CF81F0>: TypeError("callback() got multiple values for argument 'result'")
